Workbook

Sheet MARKET_BENCHMARK
A1: Category | B1: Item | C1: Cost (USD) | D1: Infos | E1: Cost
A2: Chassis | B2: Dallara IR-18 | C2: 450000 | D2: Autoweek 2012 (+*AS) | E2: High
A3: Chassis | B3: Updates | C3: 250000 | D3: Continous R&D | E3: Medium
A4: Engine | B4: Engine Lease (Season) | C4: 1700000 | D4: HPD / Chevrolet | E4: High
A5: Tires | B5: Tires Lease (259/280 sets) | C5: 1100000 | D5: Firestone | E5: High
A6: Personnel | B6: Crew | C6: 1800000 | D6: Industry Benchmark | E6: Estimate
A7: Logistics | B7: Emergency Shipping | C7: 450000 | D7: Historical Data | E7: Estimate
B8: Adjusted Logistics Costs | C8: =RND_PERFORMANCE_MODEL!B8 -> 360000 | D8: AI contribution | E8: Estimate
A10: Base Budget | C10: 8500000
A11: Core Costs | C11: =SUM(C2:C6,C8) -> 5660000
A12: Op. Overhead | C12: =C10-C11 -> 2840000
B14: What do colors mean?
B15: Internal link
B16: External link

Sheet OPERATIONAL_SIMULATOR
A1: Parameter | B1: Input / Formula | C1: Notes
A2: Total Season Distance (km) | B2: 6500 | C2: Road + Oval calendar
A3: Fuel Cost per km (USD) | B3: 3.2 | C3: Avg transport and fuel
A4: Variable Logistics Cost | B4: =B2*B3 -> 20800 | C4: Distance-based model
A5: Risk Level | B5: Low | C5: Event-based risk profile
A6: Contingency (%) | B6: =_xlfn.XLOOKUP(B5, A12:A14, B12:B14) -> 0.15 | C6: Crash probability matrix
A7: Base Budget | B7: 8500000 | C7: Typical Base Budget
A8: Contingency Fund | B8: =B6*B7 -> 1275000 | C8: (Budget * Contingency)
A11: Risk Level | B11: Contingency (%)
A12: Low | B12: 0.15
A13: Medium | B13: 0.22
A14: High | B14: 0.3

Sheet RND_PERFORMANCE_MODEL
A1: Parameter | B1: Value | C1: Description
A2: R&D Spend (USD) | B2: 1400000 | C2: Aero + simulation + testing
A3: Reliability Index (0-1) | B3: 0.92 | C3: Historical DNFs, center for random sim
A4: AI Predictive Savings (%) | B4: 0.2 | C4: McKinsey analysis
A5: Adjusted Ops Cost | B5: =OPERATIONAL_SIMULATOR!B3*(1-B3) -> 0.256 | C5: "Risk Tax" paid per km (amount lost)
A6: Expected Points Per Race | B6: =ROUND((B2/100000)*(B3*1.1),0) -> 14 | C6: Investment-to-performance
A8: Adjusted Logistics Costs | B8: =MARKET_BENCHMARK!C7 * (1 - B4) -> 360000
A9: Savings because of AI | B9: =MARKET_BENCHMARK!C7 - B8 -> 90000

Sheet HEATMAP
A1: Championship Probability Heatmap
A3: Budget \ R&D | B3: 800000 | C3: 1000000 | D3: 1200000 | E3: 1400000 | F3: 1600000
A4: 6500000 | B4: =MIN(0.9, (LN($A4/1000000)*0.12 + LN(B$3/100000)*0.08)) -> 0.39097158 | C4: =MIN(0.9, (LN($A4/1000000)*0.12 + LN(C$3/100000)*0.08)) -> 0.40882307 | D4: =MIN(0.9, (LN($A4/1000000)*0.12 + LN(D$3/100000)*0.08)) -> 0.42340879 | E4: =MIN(0.9, (LN($A4/1000000)*0.12 + LN(E$3/100000)*0.08)) -> 0.43574085 | F4: =MIN(0.9, (LN($A4/1000000)*0.12 + LN(F$3/100000)*0.08)) -> 0.44642336
A5: 7500000 | B5: =MIN(0.9, (LN($A5/1000000)*0.12 + LN(B$3/100000)*0.08)) -> 0.40814369 | C5: =MIN(0.9, (LN($A5/1000000)*0.12 + LN(C$3/100000)*0.08)) -> 0.42599517 | D5: =MIN(0.9, (LN($A5/1000000)*0.12 + LN(D$3/100000)*0.08)) -> 0.44058089 | E5: =MIN(0.9, (LN($A5/1000000)*0.12 + LN(E$3/100000)*0.08)) -> 0.45291295 | F5: =MIN(0.9, (LN($A5/1000000)*0.12 + LN(F$3/100000)*0.08)) -> 0.46359546
A6: 8500000 | B6: =MIN(0.9, (LN($A6/1000000)*0.12 + LN(B$3/100000)*0.08)) -> 0.42316326 | C6: =MIN(0.9, (LN($A6/1000000)*0.12 + LN(C$3/100000)*0.08)) -> 0.44101475 | D6: =MIN(0.9, (LN($A6/1000000)*0.12 + LN(D$3/100000)*0.08)) -> 0.45560047 | E6: =MIN(0.9, (LN($A6/1000000)*0.12 + LN(E$3/100000)*0.08)) -> 0.46793253 | F6: =MIN(0.9, (LN($A6/1000000)*0.12 + LN(F$3/100000)*0.08)) -> 0.47861504
A7: 9500000 | B7: =MIN(0.9, (LN($A7/1000000)*0.12 + LN(B$3/100000)*0.08)) -> 0.43651034 | C7: =MIN(0.9, (LN($A7/1000000)*0.12 + LN(C$3/100000)*0.08)) -> 0.45436182 | D7: =MIN(0.9, (LN($A7/1000000)*0.12 + LN(D$3/100000)*0.08)) -> 0.46894755 | E7: =MIN(0.9, (LN($A7/1000000)*0.12 + LN(E$3/100000)*0.08)) -> 0.4812796 | F7: =MIN(0.9, (LN($A7/1000000)*0.12 + LN(F$3/100000)*0.08)) -> 0.49196211
A8: 10500000 | B8: =MIN(0.9, (LN($A8/1000000)*0.12 + LN(B$3/100000)*0.08)) -> 0.44852035 | C8: =MIN(0.9, (LN($A8/1000000)*0.12 + LN(C$3/100000)*0.08)) -> 0.46637184 | D8: =MIN(0.9, (LN($A8/1000000)*0.12 + LN(D$3/100000)*0.08)) -> 0.48095756 | E8: =MIN(0.9, (LN($A8/1000000)*0.12 + LN(E$3/100000)*0.08)) -> 0.49328962 | F8: =MIN(0.9, (LN($A8/1000000)*0.12 + LN(F$3/100000)*0.08)) -> 0.50397213

Sheet MONTE_CARLO_SIM
B1: R&D Scenario | C1: Reliability* | D1: Points Outcome | R1: High | S1: Medium | T1: Low
B2: =RND_PERFORMANCE_MODEL!B2*(0.8+RAND()*0.4) -> 1142584.9 | C2: =RND_PERFORMANCE_MODEL!B3*(0.9+RAND()*0.2) -> 0.93653793 | D2: =ROUND((B2 /100000)*(C2*1.1),0) -> 12 | R2: =IF(C2>=0.95, D2, NA()) -> #N/A | S2: =IF(AND(C2<0.95, C2>=0.9), D2, NA()) -> 12 | T2: =IF(C2<0.9, D2, NA()) -> #N/A
B3: =RND_PERFORMANCE_MODEL!B2*(0.8+RAND()*0.4) -> 1414190.6 | C3: =RND_PERFORMANCE_MODEL!B3*(0.9+RAND()*0.2) -> 0.83124047 | D3: =ROUND((B3 /100000)*(C3*1.1),0) -> 13 | R3: =IF(C3>=0.95, D3, NA()) -> #N/A | S3: =IF(AND(C3<0.95, C3>=0.9), D3, NA()) -> #N/A | T3: =IF(C3<0.9, D3, NA()) -> 13
B4: =RND_PERFORMANCE_MODEL!B2*(0.8+RAND()*0.4) -> 1127073.6 | C4: =RND_PERFORMANCE_MODEL!B3*(0.9+RAND()*0.2) -> 0.83280557 | D4: =ROUND((B4 /100000)*(C4*1.1),0) -> 10 | R4: =IF(C4>=0.95, D4, NA()) -> #N/A | S4: =IF(AND(C4<0.95, C4>=0.9), D4, NA()) -> #N/A | T4: =IF(C4<0.9, D4, NA()) -> 10
B5: =RND_PERFORMANCE_MODEL!B2*(0.8+RAND()*0.4) -> 1597879.8 | C5: =RND_PERFORMANCE_MODEL!B3*(0.9+RAND()*0.2) -> 0.86321345 | D5: =ROUND((B5 /100000)*(C5*1.1),0) -> 15 | R5: =IF(C5>=0.95, D5, NA()) -> #N/A | S5: =IF(AND(C5<0.95, C5>=0.9), D5, NA()) -> #N/A | T5: =IF(C5<0.9, D5, NA()) -> 15
B6: =RND_PERFORMANCE_MODEL!B2*(0.8+RAND()*0.4) -> 1329512.9 | C6: =RND_PERFORMANCE_MODEL!B3*(0.9+RAND()*0.2) -> 0.88383742 | D6: =ROUND((B6 /100000)*(C6*1.1),0) -> 13 | R6: =IF(C6>=0.95, D6, NA()) -> #N/A | S6: =IF(AND(C6<0.95, C6>=0.9), D6, NA()) -> #N/A | T6: =IF(C6<0.9, D6, NA()) -> 13
B7: =RND_PERFORMANCE_MODEL!B2*(0.8+RAND()*0.4) -> 1405172.5 | C7: =RND_PERFORMANCE_MODEL!B3*(0.9+RAND()*0.2) -> 0.87267805 | D7: =ROUND((B7 /100000)*(C7*1.1),0) -> 13 | R7: =IF(C7>=0.95, D7, NA()) -> #N/A | S7: =IF(AND(C7<0.95, C7>=0.9), D7, NA()) -> #N/A | T7: =IF(C7<0.9, D7, NA()) -> 13
B8: =RND_PERFORMANCE_MODEL!B2*(0.8+RAND()*0.4) -> 1591702.4 | C8: =RND_PERFORMANCE_MODEL!B3*(0.9+RAND()*0.2) -> 0.95059246 | D8: =ROUND((B8 /100000)*(C8*1.1),0) -> 17 | R8: =IF(C8>=0.95, D8, NA()) -> 17 | S8: =IF(AND(C8<0.95, C8>=0.9), D8, NA()) -> #N/A | T8: =IF(C8<0.9, D8, NA()) -> #N/A
B9: =RND_PERFORMANCE_MODEL!B2*(0.8+RAND()*0.4) -> 1305159.6 | C9: =RND_PERFORMANCE_MODEL!B3*(0.9+RAND()*0.2) -> 0.96464835 | D9: =ROUND((B9 /100000)*(C9*1.1),0) -> 14 | R9: =IF(C9>=0.95, D9, NA()) -> 14 | S9: =IF(AND(C9<0.95, C9>=0.9), D9, NA()) -> #N/A | T9: =IF(C9<0.9, D9, NA()) -> #N/A
B10: =RND_PERFORMANCE_MODEL!B2*(0.8+RAND()*0.4) -> 1486726 | C10: =RND_PERFORMANCE_MODEL!B3*(0.9+RAND()*0.2) -> 0.98611412 | D10: =ROUND((B10 /100000)*(C10*1.1),0) -> 16 | R10: =IF(C10>=0.95, D10, NA()) -> 16 | S10: =IF(AND(C10<0.95, C10>=0.9), D10, NA()) -> #N/A | T10: =IF(C10<0.9, D10, NA()) -> #N/A
B11: =RND_PERFORMANCE_MODEL!B2*(0.8+RAND()*0.4) -> 1409435.8 | C11: =RND_PERFORMANCE_MODEL!B3*(0.9+RAND()*0.2) -> 0.93304225 | D11: =ROUND((B11 /100000)*(C11*1.1),0) -> 14 | R11: =IF(C11>=0.95, D11, NA()) -> #N/A | S11: =IF(AND(C11<0.95, C11>=0.9), D11, NA()) -> 14 | T11: =IF(C11<0.9, D11, NA()) -> #N/A
B12: =RND_PERFORMANCE_MODEL!B2*(0.8+RAND()*0.4) -> 1140985.9 | C12: =RND_PERFORMANCE_MODEL!B3*(0.9+RAND()*0.2) -> 0.97838625 | D12: =ROUND((B12 /100000)*(C12*1.1),0) -> 12 | R12: =IF(C12>=0.95, D12, NA()) -> 12 | S12: =IF(AND(C12<0.95, C12>=0.9), D12, NA()) -> #N/A | T12: =IF(C12<0.9, D12, NA()) -> #N/A
B13: =RND_PERFORMANCE_MODEL!B2*(0.8+RAND()*0.4) -> 1285086.6 | C13: =RND_PERFORMANCE_MODEL!B3*(0.9+RAND()*0.2) -> 0.91645826 | D13: =ROUND((B13 /100000)*(C13*1.1),0) -> 13 | R13: =IF(C13>=0.95, D13, NA()) -> #N/A | S13: =IF(AND(C13<0.95, C13>=0.9), D13, NA()) -> 13 | T13: =IF(C13<0.9, D13, NA()) -> #N/A
B14: =RND_PERFORMANCE_MODEL!B2*(0.8+RAND()*0.4) -> 1355662.7 | C14: =RND_PERFORMANCE_MODEL!B3*(0.9+RAND()*0.2) -> 0.85693772 | D14: =ROUND((B14 /100000)*(C14*1.1),0) -> 13 | R14: =IF(C14>=0.95, D14, NA()) -> #N/A | S14: =IF(AND(C14<0.95, C14>=0.9), D14, NA()) -> #N/A | T14: =IF(C14<0.9, D14, NA()) -> 13
B15: =RND_PERFORMANCE_MODEL!B2*(0.8+RAND()*0.4) -> 1663709 | C15: =RND_PERFORMANCE_MODEL!B3*(0.9+RAND()*0.2) -> 0.86430434 | D15: =ROUND((B15 /100000)*(C15*1.1),0) -> 16 | R15: =IF(C15>=0.95, D15, NA()) -> #N/A | S15: =IF(AND(C15<0.95, C15>=0.9), D15, NA()) -> #N/A | T15: =IF(C15<0.9, D15, NA()) -> 16
B16: =RND_PERFORMANCE_MODEL!B2*(0.8+RAND()*0.4) -> 1543916.3 | C16: =RND_PERFORMANCE_MODEL!B3*(0.9+RAND()*0.2) -> 0.93941455 | D16: =ROUND((B16 /100000)*(C16*1.1),0) -> 16 | R16: =IF(C16>=0.95, D16, NA()) -> #N/A | S16: =IF(AND(C16<0.95, C16>=0.9), D16, NA()) -> 16 | T16: =IF(C16<0.9, D16, NA()) -> #N/A
B17: =RND_PERFORMANCE_MODEL!B2*(0.8+RAND()*0.4) -> 1281668.2 | C17: =RND_PERFORMANCE_MODEL!B3*(0.9+RAND()*0.2) -> 0.94303887 | D17: =ROUND((B17 /100000)*(C17*1.1),0) -> 13 | R17: =IF(C17>=0.95, D17, NA()) -> #N/A | S17: =IF(AND(C17<0.95, C17>=0.9), D17, NA()) -> 13 | T17: =IF(C17<0.9, D17, NA()) -> #N/A
B18: =RND_PERFORMANCE_MODEL!B2*(0.8+RAND()*0.4) -> 1309419.8 | C18: =RND_PERFORMANCE_MODEL!B3*(0.9+RAND()*0.2) -> 0.9790877 | D18: =ROUND((B18 /100000)*(C18*1.1),0) -> 14 | R18: =IF(C18>=0.95, D18, NA()) -> 14 | S18: =IF(AND(C18<0.95, C18>=0.9), D18, NA()) -> #N/A | T18: =IF(C18<0.9, D18, NA()) -> #N/A
B19: =RND_PERFORMANCE_MODEL!B2*(0.8+RAND()*0.4) -> 1642958.8 | C19: =RND_PERFORMANCE_MODEL!B3*(0.9+RAND()*0.2) -> 0.86084448 | D19: =ROUND((B19 /100000)*(C19*1.1),0) -> 16 | R19: =IF(C19>=0.95, D19, NA()) -> #N/A | S19: =IF(AND(C19<0.95, C19>=0.9), D19, NA()) -> #N/A | T19: =IF(C19<0.9, D19, NA()) -> 16
B20: =RND_PERFORMANCE_MODEL!B2*(0.8+RAND()*0.4) -> 1353086 | C20: =RND_PERFORMANCE_MODEL!B3*(0.9+RAND()*0.2) -> 0.8994677 | D20: =ROUND((B20 /100000)*(C20*1.1),0) -> 13 | R20: =IF(C20>=0.95, D20, NA()) -> #N/A | S20: =IF(AND(C20<0.95, C20>=0.9), D20, NA()) -> #N/A | T20: =IF(C20<0.9, D20, NA()) -> 13
B21: =RND_PERFORMANCE_MODEL!B2*(0.8+RAND()*0.4) -> 1590919.5 | C21: =RND_PERFORMANCE_MODEL!B3*(0.9+RAND()*0.2) -> 0.86702074 | D21: =ROUND((B21 /100000)*(C21*1.1),0) -> 15 | R21: =IF(C21>=0.95, D21, NA()) -> #N/A | S21: =IF(AND(C21<0.95, C21>=0.9), D21, NA()) -> #N/A | T21: =IF(C21<0.9, D21, NA()) -> 15
B22: =RND_PERFORMANCE_MODEL!B2*(0.8+RAND()*0.4) -> 1423350.3 | C22: =RND_PERFORMANCE_MODEL!B3*(0.9+RAND()*0.2) -> 0.84341784 | D22: =ROUND((B22 /100000)*(C22*1.1),0) -> 13 | R22: =IF(C22>=0.95, D22, NA()) -> #N/A | S22: =IF(AND(C22<0.95, C22>=0.9), D22, NA()) -> #N/A | T22: =IF(C22<0.9, D22, NA()) -> 13
B23: =RND_PERFORMANCE_MODEL!B2*(0.8+RAND()*0.4) -> 1237656.7 | C23: =RND_PERFORMANCE_MODEL!B3*(0.9+RAND()*0.2) -> 1.0066037 | D23: =ROUND((B23 /100000)*(C23*1.1),0) -> 14 | R23: =IF(C23>=0.95, D23, NA()) -> 14 | S23: =IF(AND(C23<0.95, C23>=0.9), D23, NA()) -> #N/A | T23: =IF(C23<0.9, D23, NA()) -> #N/A
B24: =RND_PERFORMANCE_MODEL!B2*(0.8+RAND()*0.4) -> 1390417.1 | C24: =RND_PERFORMANCE_MODEL!B3*(0.9+RAND()*0.2) -> 0.92536166 | D24: =ROUND((B24 /100000)*(C24*1.1),0) -> 14 | R24: =IF(C24>=0.95, D24, NA()) -> #N/A | S24: =IF(AND(C24<0.95, C24>=0.9), D24, NA()) -> 14 | T24: =IF(C24<0.9, D24, NA()) -> #N/A
B25: =RND_PERFORMANCE_MODEL!B2*(0.8+RAND()*0.4) -> 1603931.6 | C25: =RND_PERFORMANCE_MODEL!B3*(0.9+RAND()*0.2) -> 0.91813578 | D25: =ROUND((B25 /100000)*(C25*1.1),0) -> 16 | R25: =IF(C25>=0.95, D25, NA()) -> #N/A | S25: =IF(AND(C25<0.95, C25>=0.9), D25, NA()) -> 16 | T25: =IF(C25<0.9, D25, NA()) -> #N/A
B26: =RND_PERFORMANCE_MODEL!B2*(0.8+RAND()*0.4) -> 1484071.9 | C26: =RND_PERFORMANCE_MODEL!B3*(0.9+RAND()*0.2) -> 0.96112764 | D26: =ROUND((B26 /100000)*(C26*1.1),0) -> 16 | R26: =IF(C26>=0.95, D26, NA()) -> 16 | S26: =IF(AND(C26<0.95, C26>=0.9), D26, NA()) -> #N/A | T26: =IF(C26<0.9, D26, NA()) -> #N/A
B27: =RND_PERFORMANCE_MODEL!B2*(0.8+RAND()*0.4) -> 1169966.2 | C27: =RND_PERFORMANCE_MODEL!B3*(0.9+RAND()*0.2) -> 0.88203881 | D27: =ROUND((B27 /100000)*(C27*1.1),0) -> 11 | R27: =IF(C27>=0.95, D27, NA()) -> #N/A | S27: =IF(AND(C27<0.95, C27>=0.9), D27, NA()) -> #N/A | T27: =IF(C27<0.9, D27, NA()) -> 11
B28: =RND_PERFORMANCE_MODEL!B2*(0.8+RAND()*0.4) -> 1602417.6 | C28: =RND_PERFORMANCE_MODEL!B3*(0.9+RAND()*0.2) -> 0.99110956 | D28: =ROUND((B28 /100000)*(C28*1.1),0) -> 17 | R28: =IF(C28>=0.95, D28, NA()) -> 17 | S28: =IF(AND(C28<0.95, C28>=0.9), D28, NA()) -> #N/A | T28: =IF(C28<0.9, D28, NA()) -> #N/A
B29: =RND_PERFORMANCE_MODEL!B2*(0.8+RAND()*0.4) -> 1131565.3 | C29: =RND_PERFORMANCE_MODEL!B3*(0.9+RAND()*0.2) -> 0.99260333 | D29: =ROUND((B29 /100000)*(C29*1.1),0) -> 12 | R29: =IF(C29>=0.95, D29, NA()) -> 12 | S29: =IF(AND(C29<0.95, C29>=0.9), D29, NA()) -> #N/A | T29: =IF(C29<0.9, D29, NA()) -> #N/A
B30: =RND_PERFORMANCE_MODEL!B2*(0.8+RAND()*0.4) -> 1378720 | C30: =RND_PERFORMANCE_MODEL!B3*(0.9+RAND()*0.2) -> 0.97322339 | D30: =ROUND((B30 /100000)*(C30*1.1),0) -> 15 | R30: =IF(C30>=0.95, D30, NA()) -> 15 | S30: =IF(AND(C30<0.95, C30>=0.9), D30, NA()) -> #N/A | T30: =IF(C30<0.9, D30, NA()) -> #N/A
B31: =RND_PERFORMANCE_MODEL!B2*(0.8+RAND()*0.4) -> 1136086.6 | C31: =RND_PERFORMANCE_MODEL!B3*(0.9+RAND()*0.2) -> 0.90854469 | D31: =ROUND((B31 /100000)*(C31*1.1),0) -> 11 | R31: =IF(C31>=0.95, D31, NA()) -> #N/A | S31: =IF(AND(C31<0.95, C31>=0.9), D31, NA()) -> 11 | T31: =IF(C31<0.9, D31, NA()) -> #N/A
B32: =RND_PERFORMANCE_MODEL!B2*(0.8+RAND()*0.4) -> 1218074.8 | C32: =RND_PERFORMANCE_MODEL!B3*(0.9+RAND()*0.2) -> 0.91482 | D32: =ROUND((B32 /100000)*(C32*1.1),0) -> 12 | R32: =IF(C32>=0.95, D32, NA()) -> #N/A | S32: =IF(AND(C32<0.95, C32>=0.9), D32, NA()) -> 12 | T32: =IF(C32<0.9, D32, NA()) -> #N/A
B33: =RND_PERFORMANCE_MODEL!B2*(0.8+RAND()*0.4) -> 1286173.8 | C33: =RND_PERFORMANCE_MODEL!B3*(0.9+RAND()*0.2) -> 0.91931297 | D33: =ROUND((B33 /100000)*(C33*1.1),0) -> 13 | R33: =IF(C33>=0.95, D33, NA()) -> #N/A | S33: =IF(AND(C33<0.95, C33>=0.9), D33, NA()) -> 13 | T33: =IF(C33<0.9, D33, NA()) -> #N/A
B34: =RND_PERFORMANCE_MODEL!B2*(0.8+RAND()*0.4) -> 1343217.5 | C34: =RND_PERFORMANCE_MODEL!B3*(0.9+RAND()*0.2) -> 0.93353682 | D34: =ROUND((B34 /100000)*(C34*1.1),0) -> 14 | R34: =IF(C34>=0.95, D34, NA()) -> #N/A | S34: =IF(AND(C34<0.95, C34>=0.9), D34, NA()) -> 14 | T34: =IF(C34<0.9, D34, NA()) -> #N/A
B35: =RND_PERFORMANCE_MODEL!B2*(0.8+RAND()*0.4) -> 1328653.4 | C35: =RND_PERFORMANCE_MODEL!B3*(0.9+RAND()*0.2) -> 0.90297548 | D35: =ROUND((B35 /100000)*(C35*1.1),0) -> 13 | R35: =IF(C35>=0.95, D35, NA()) -> #N/A | S35: =IF(AND(C35<0.95, C35>=0.9), D35, NA()) -> 13 | T35: =IF(C35<0.9, D35, NA()) -> #N/A
B36: =RND_PERFORMANCE_MODEL!B2*(0.8+RAND()*0.4) -> 1248140.2 | C36: =RND_PERFORMANCE_MODEL!B3*(0.9+RAND()*0.2) -> 0.9875714 | D36: =ROUND((B36 /100000)*(C36*1.1),0) -> 14 | R36: =IF(C36>=0.95, D36, NA()) -> 14 | S36: =IF(AND(C36<0.95, C36>=0.9), D36, NA()) -> #N/A | T36: =IF(C36<0.9, D36, NA()) -> #N/A
B37: =RND_PERFORMANCE_MODEL!B2*(0.8+RAND()*0.4) -> 1224421.6 | C37: =RND_PERFORMANCE_MODEL!B3*(0.9+RAND()*0.2) -> 0.9886823 | D37: =ROUND((B37 /100000)*(C37*1.1),0) -> 13 | R37: =IF(C37>=0.95, D37, NA()) -> 13 | S37: =IF(AND(C37<0.95, C37>=0.9), D37, NA()) -> #N/A | T37: =IF(C37<0.9, D37, NA()) -> #N/A
B38: =RND_PERFORMANCE_MODEL!B2*(0.8+RAND()*0.4) -> 1141820.8 | C38: =RND_PERFORMANCE_MODEL!B3*(0.9+RAND()*0.2) -> 0.89062376 | D38: =ROUND((B38 /100000)*(C38*1.1),0) -> 11 | R38: =IF(C38>=0.95, D38, NA()) -> #N/A | S38: =IF(AND(C38<0.95, C38>=0.9), D38, NA()) -> #N/A | T38: =IF(C38<0.9, D38, NA()) -> 11
B39: =RND_PERFORMANCE_MODEL!B2*(0.8+RAND()*0.4) -> 1174478.2 | C39: =RND_PERFORMANCE_MODEL!B3*(0.9+RAND()*0.2) -> 1.0016689 | D39: =ROUND((B39 /100000)*(C39*1.1),0) -> 13 | R39: =IF(C39>=0.95, D39, NA()) -> 13 | S39: =IF(AND(C39<0.95, C39>=0.9), D39, NA()) -> #N/A | T39: =IF(C39<0.9, D39, NA()) -> #N/A
B40: =RND_PERFORMANCE_MODEL!B2*(0.8+RAND()*0.4) -> 1342632 | C40: =RND_PERFORMANCE_MODEL!B3*(0.9+RAND()*0.2) -> 1.0005912 | D40: =ROUND((B40 /100000)*(C40*1.1),0) -> 15 | R40: =IF(C40>=0.95, D40, NA()) -> 15 | S40: =IF(AND(C40<0.95, C40>=0.9), D40, NA()) -> #N/A | T40: =IF(C40<0.9, D40, NA()) -> #N/A
...

Sheet EXECUTIVE
A1: Metric | B1: Value | C1: Interpretation
A2: Total Budget | B2: =OPERATIONAL_SIMULATOR!B7 + RND_PERFORMANCE_MODEL!B2 + OPERATIONAL_SIMULATOR!B8 -> 11175000 | C2: Seasonal budget
A3: Total Ops Cost | B3: =OPERATIONAL_SIMULATOR!B7 + (MARKET_BENCHMARK!C7 * (1 - RND_PERFORMANCE_MODEL!B4)) -> 8860000 | C3: Base + contingency
A4: R&D Spend | B4: =RND_PERFORMANCE_MODEL!B2 -> 1400000 | C4: Investment
A5: Expected Points per race | B5: =RND_PERFORMANCE_MODEL!B6 -> 14 | C5: Mean outcome
A6: Number of Races | B6: 17 | C6: Schedule
A7: Expected Points (total) | B7: =(B5*B6) -> 238 | C7: Estimate
A8: Performance-per-Dollar (PPD) | B8: =((B5 * 17) / B2) * 1000000 -> 21.297539 | C8: points/$1M spent
